Workbook

Sheet Recruit Monitoring Tracker
A1: RECRUIT MONITORING TRACKER
A2: Agent Recruitment Pipeline | Candidate Profiling, ADD (Discovery Day) & LMS (Learning Modules) Tracker
B4: TOTAL RECRUITS TRACKED | F4: ATTENDED ADD | J4: LMS IN PROGRESS | N4: COMPLETED LMS | R4: FUNNEL CONVERSION
B5: =COUNTA(B9:B65) | F5: =COUNTIF(H9:H65, "Yes") | J5: =COUNTIF(L9:L65, "In Progress") | N5: =COUNTIF(L9:L65, "Yes") | R5: =IFERROR(COUNTIF(L9:L65,"Yes")/COUNTA(B9:B65),0)
B6: Active candidates in pipeline | F6: ="Attendance Rate: " & TEXT(IFERROR(COUNTIF(H9:H65,"Yes")/COUNTA(B9:B65),0),"0.0%") | J6: Currently processing modules | N6: ="Completion Rate: " & TEXT(IFERROR(COUNTIF(L9:L65,"Yes")/COUNTIF(H9:H65,"Yes"),0),"0.0%") | R6: Total Recruits -> LMS Certified
A7: CANDIDATE INFORMATION | G7: STAGE 1: ADD (AGENCY DISCOVERY DAY) | K7: STAGE 2: LMS (LEARNING MANAGEMENT SYSTEM) | P7: PIPELINE STATUS & NEXT ACTIONS
A8: Recruit ID | B8: Complete Name | C8: Contact Number | D8: Email Address | E8: Sourced By | F8: Date Sourced | G8: ADD Scheduled Date | H8: Attended ADD? | I8: ADD Attendance Date | J8: ADD Remarks / Feedback | K8: LMS Access Date | L8: Completed LMS? | M8: LMS Completion Date | N8: LMS Progress % | O8: LMS Score / Certificate | P8: Current Pipeline Stage | Q8: Next Action Required | R8: Target Follow-up Date | S8: Recruiter Notes
A9: REC-001 | B9: Grandes, Maybe | E9: Cedric (cedric.axa1@gmail.com) | F9: 46279 | G9: 46279 | H9: Yes | I9: 46279 | J9: Attended ADD on Sept 14; confirmed proceeding with LMS training. | K9: 46280 | L9: In Progress | N9: 0 | O9: Account registration in progress | P9: =IF(B9="","",IF(L9="Yes","LMS Completed (Ready for Exam)",IF(L9="In Progress","LMS In Progress",IF(H9="Yes","ADD Attended - Awaiting LMS",IF(H9="Rescheduled","ADD Rescheduled",IF(H9="Pending","ADD Scheduled",IF(H9="No","ADD Missed - Follow Up","Initial Prospect"))))))) | Q9: Process LMS portal registration & send login access link today | R9: 46280 | S9: Attended ADD yesterday Sept 14, 2026. Processing her LMS onboarding today.
A10: REC-002 | B10: Bagiuos, Michael | E10: Cedric (cedric.axa1@gmail.com) | F10: 46279 | G10: 46279 | H10: Yes | I10: 46279 | J10: Attended ADD on Sept 14; not yet processing LMS. | L10: Not Started | N10: 0 | P10: =IF(B10="","",IF(L10="Yes","LMS Completed (Ready for Exam)",IF(L10="In Progress","LMS In Progress",IF(H10="Yes","ADD Attended - Awaiting LMS",IF(H10="Rescheduled","ADD Rescheduled",IF(H10="Pending","ADD Scheduled",IF(H10="No","ADD Missed - Follow Up","Initial Prospect"))))))) | Q10: Follow up on ADD feedback & check readiness to process LMS | R10: 46281 | S10: Attended ADD yesterday Sept 14, 2026. Pending decision to proceed with LMS.
A11: REC-003 | B11: Barilea, Alona | E11: Cedric (cedric.axa1@gmail.com) | F11: 46279 | G11: 46279 | H11: Yes | I11: 46279 | J11: Attended ADD on Sept 14; not yet processing LMS. | L11: Not Started | N11: 0 | P11: =IF(B11="","",IF(L11="Yes","LMS Completed (Ready for Exam)",IF(L11="In Progress","LMS In Progress",IF(H11="Yes","ADD Attended - Awaiting LMS",IF(H11="Rescheduled","ADD Rescheduled",IF(H11="Pending","ADD Scheduled",IF(H11="No","ADD Missed - Follow Up","Initial Prospect"))))))) | Q11: Follow up on ADD feedback & check readiness to process LMS | R11: 46281 | S11: Attended ADD yesterday Sept 14, 2026. Pending decision to proceed with LMS.
A12: REC-004 | B12: Garrucha, Lorenz | E12: Cedric (cedric.axa1@gmail.com) | F12: 46279 | G12: 46279 | H12: Yes | I12: 46279 | J12: Attended ADD on Sept 14; not yet processing LMS. | L12: Not Started | N12: 0 | P12: =IF(B12="","",IF(L12="Yes","LMS Completed (Ready for Exam)",IF(L12="In Progress","LMS In Progress",IF(H12="Yes","ADD Attended - Awaiting LMS",IF(H12="Rescheduled","ADD Rescheduled",IF(H12="Pending","ADD Scheduled",IF(H12="No","ADD Missed - Follow Up","Initial Prospect"))))))) | Q12: Follow up on ADD feedback & check readiness to process LMS | R12: 46281 | S12: Attended ADD yesterday Sept 14, 2026. Pending decision to proceed with LMS.
A13: REC-005 | B13: Ambos, Princess | E13: Cedric (cedric.axa1@gmail.com) | F13: 46279 | G13: 46279 | H13: Yes | I13: 46279 | J13: Attended ADD on Sept 14; not yet processing LMS. | L13: Not Started | N13: 0 | P13: =IF(B13="","",IF(L13="Yes","LMS Completed (Ready for Exam)",IF(L13="In Progress","LMS In Progress",IF(H13="Yes","ADD Attended - Awaiting LMS",IF(H13="Rescheduled","ADD Rescheduled",IF(H13="Pending","ADD Scheduled",IF(H13="No","ADD Missed - Follow Up","Initial Prospect"))))))) | Q13: Follow up on ADD feedback & check readiness to process LMS | R13: 46281 | S13: Attended ADD yesterday Sept 14, 2026. Pending decision to proceed with LMS.
A14: REC-006 | B14: Montano, Jezreel Kate | E14: Cedric (cedric.axa1@gmail.com) | F14: 46279 | G14: 46279 | H14: Yes | I14: 46279 | J14: Attended ADD on Sept 14; not yet processing LMS. | L14: Not Started | N14: 0 | P14: =IF(B14="","",IF(L14="Yes","LMS Completed (Ready for Exam)",IF(L14="In Progress","LMS In Progress",IF(H14="Yes","ADD Attended - Awaiting LMS",IF(H14="Rescheduled","ADD Rescheduled",IF(H14="Pending","ADD Scheduled",IF(H14="No","ADD Missed - Follow Up","Initial Prospect"))))))) | Q14: Follow up on ADD feedback & check readiness to process LMS | R14: 46281 | S14: Attended ADD yesterday Sept 14, 2026. Pending decision to proceed with LMS.
A15: =IF(B15="","","REC-"&TEXT(15-8,"000")) | P15: =IF(B15="","",IF(L15="Yes","LMS Completed (Ready for Exam)",IF(L15="In Progress","LMS In Progress",IF(H15="Yes","ADD Attended - Awaiting LMS",IF(H15="Rescheduled","ADD Rescheduled",IF(H15="Pending","ADD Scheduled",IF(H15="No","ADD Missed - Follow Up","Initial Prospect")))))))
A16: =IF(B16="","","REC-"&TEXT(16-8,"000")) | P16: =IF(B16="","",IF(L16="Yes","LMS Completed (Ready for Exam)",IF(L16="In Progress","LMS In Progress",IF(H16="Yes","ADD Attended - Awaiting LMS",IF(H16="Rescheduled","ADD Rescheduled",IF(H16="Pending","ADD Scheduled",IF(H16="No","ADD Missed - Follow Up","Initial Prospect")))))))
A17: =IF(B17="","","REC-"&TEXT(17-8,"000")) | P17: =IF(B17="","",IF(L17="Yes","LMS Completed (Ready for Exam)",IF(L17="In Progress","LMS In Progress",IF(H17="Yes","ADD Attended - Awaiting LMS",IF(H17="Rescheduled","ADD Rescheduled",IF(H17="Pending","ADD Scheduled",IF(H17="No","ADD Missed - Follow Up","Initial Prospect")))))))
A18: =IF(B18="","","REC-"&TEXT(18-8,"000")) | P18: =IF(B18="","",IF(L18="Yes","LMS Completed (Ready for Exam)",IF(L18="In Progress","LMS In Progress",IF(H18="Yes","ADD Attended - Awaiting LMS",IF(H18="Rescheduled","ADD Rescheduled",IF(H18="Pending","ADD Scheduled",IF(H18="No","ADD Missed - Follow Up","Initial Prospect")))))))
A19: =IF(B19="","","REC-"&TEXT(19-8,"000")) | P19: =IF(B19="","",IF(L19="Yes","LMS Completed (Ready for Exam)",IF(L19="In Progress","LMS In Progress",IF(H19="Yes","ADD Attended - Awaiting LMS",IF(H19="Rescheduled","ADD Rescheduled",IF(H19="Pending","ADD Scheduled",IF(H19="No","ADD Missed - Follow Up","Initial Prospect")))))))
A20: =IF(B20="","","REC-"&TEXT(20-8,"000")) | P20: =IF(B20="","",IF(L20="Yes","LMS Completed (Ready for Exam)",IF(L20="In Progress","LMS In Progress",IF(H20="Yes","ADD Attended - Awaiting LMS",IF(H20="Rescheduled","ADD Rescheduled",IF(H20="Pending","ADD Scheduled",IF(H20="No","ADD Missed - Follow Up","Initial Prospect")))))))
A21: =IF(B21="","","REC-"&TEXT(21-8,"000")) | P21: =IF(B21="","",IF(L21="Yes","LMS Completed (Ready for Exam)",IF(L21="In Progress","LMS In Progress",IF(H21="Yes","ADD Attended - Awaiting LMS",IF(H21="Rescheduled","ADD Rescheduled",IF(H21="Pending","ADD Scheduled",IF(H21="No","ADD Missed - Follow Up","Initial Prospect")))))))
A22: =IF(B22="","","REC-"&TEXT(22-8,"000")) | P22: =IF(B22="","",IF(L22="Yes","LMS Completed (Ready for Exam)",IF(L22="In Progress","LMS In Progress",IF(H22="Yes","ADD Attended - Awaiting LMS",IF(H22="Rescheduled","ADD Rescheduled",IF(H22="Pending","ADD Scheduled",IF(H22="No","ADD Missed - Follow Up","Initial Prospect")))))))
A23: =IF(B23="","","REC-"&TEXT(23-8,"000")) | P23: =IF(B23="","",IF(L23="Yes","LMS Completed (Ready for Exam)",IF(L23="In Progress","LMS In Progress",IF(H23="Yes","ADD Attended - Awaiting LMS",IF(H23="Rescheduled","ADD Rescheduled",IF(H23="Pending","ADD Scheduled",IF(H23="No","ADD Missed - Follow Up","Initial Prospect")))))))
A24: =IF(B24="","","REC-"&TEXT(24-8,"000")) | P24: =IF(B24="","",IF(L24="Yes","LMS Completed (Ready for Exam)",IF(L24="In Progress","LMS In Progress",IF(H24="Yes","ADD Attended - Awaiting LMS",IF(H24="Rescheduled","ADD Rescheduled",IF(H24="Pending","ADD Scheduled",IF(H24="No","ADD Missed - Follow Up","Initial Prospect")))))))
A25: =IF(B25="","","REC-"&TEXT(25-8,"000")) | P25: =IF(B25="","",IF(L25="Yes","LMS Completed (Ready for Exam)",IF(L25="In Progress","LMS In Progress",IF(H25="Yes","ADD Attended - Awaiting LMS",IF(H25="Rescheduled","ADD Rescheduled",IF(H25="Pending","ADD Scheduled",IF(H25="No","ADD Missed - Follow Up","Initial Prospect")))))))
A26: =IF(B26="","","REC-"&TEXT(26-8,"000")) | P26: =IF(B26="","",IF(L26="Yes","LMS Completed (Ready for Exam)",IF(L26="In Progress","LMS In Progress",IF(H26="Yes","ADD Attended - Awaiting LMS",IF(H26="Rescheduled","ADD Rescheduled",IF(H26="Pending","ADD Scheduled",IF(H26="No","ADD Missed - Follow Up","Initial Prospect")))))))
A27: =IF(B27="","","REC-"&TEXT(27-8,"000")) | P27: =IF(B27="","",IF(L27="Yes","LMS Completed (Ready for Exam)",IF(L27="In Progress","LMS In Progress",IF(H27="Yes","ADD Attended - Awaiting LMS",IF(H27="Rescheduled","ADD Rescheduled",IF(H27="Pending","ADD Scheduled",IF(H27="No","ADD Missed - Follow Up","Initial Prospect")))))))
A28: =IF(B28="","","REC-"&TEXT(28-8,"000")) | P28: =IF(B28="","",IF(L28="Yes","LMS Completed (Ready for Exam)",IF(L28="In Progress","LMS In Progress",IF(H28="Yes","ADD Attended - Awaiting LMS",IF(H28="Rescheduled","ADD Rescheduled",IF(H28="Pending","ADD Scheduled",IF(H28="No","ADD Missed - Follow Up","Initial Prospect")))))))
A29: =IF(B29="","","REC-"&TEXT(29-8,"000")) | P29: =IF(B29="","",IF(L29="Yes","LMS Completed (Ready for Exam)",IF(L29="In Progress","LMS In Progress",IF(H29="Yes","ADD Attended - Awaiting LMS",IF(H29="Rescheduled","ADD Rescheduled",IF(H29="Pending","ADD Scheduled",IF(H29="No","ADD Missed - Follow Up","Initial Prospect")))))))
A30: =IF(B30="","","REC-"&TEXT(30-8,"000")) | P30: =IF(B30="","",IF(L30="Yes","LMS Completed (Ready for Exam)",IF(L30="In Progress","LMS In Progress",IF(H30="Yes","ADD Attended - Awaiting LMS",IF(H30="Rescheduled","ADD Rescheduled",IF(H30="Pending","ADD Scheduled",IF(H30="No","ADD Missed - Follow Up","Initial Prospect")))))))
A31: =IF(B31="","","REC-"&TEXT(31-8,"000")) | P31: =IF(B31="","",IF(L31="Yes","LMS Completed (Ready for Exam)",IF(L31="In Progress","LMS In Progress",IF(H31="Yes","ADD Attended - Awaiting LMS",IF(H31="Rescheduled","ADD Rescheduled",IF(H31="Pending","ADD Scheduled",IF(H31="No","ADD Missed - Follow Up","Initial Prospect")))))))
A32: =IF(B32="","","REC-"&TEXT(32-8,"000")) | P32: =IF(B32="","",IF(L32="Yes","LMS Completed (Ready for Exam)",IF(L32="In Progress","LMS In Progress",IF(H32="Yes","ADD Attended - Awaiting LMS",IF(H32="Rescheduled","ADD Rescheduled",IF(H32="Pending","ADD Scheduled",IF(H32="No","ADD Missed - Follow Up","Initial Prospect")))))))
A33: =IF(B33="","","REC-"&TEXT(33-8,"000")) | P33: =IF(B33="","",IF(L33="Yes","LMS Completed (Ready for Exam)",IF(L33="In Progress","LMS In Progress",IF(H33="Yes","ADD Attended - Awaiting LMS",IF(H33="Rescheduled","ADD Rescheduled",IF(H33="Pending","ADD Scheduled",IF(H33="No","ADD Missed - Follow Up","Initial Prospect")))))))
A34: =IF(B34="","","REC-"&TEXT(34-8,"000")) | P34: =IF(B34="","",IF(L34="Yes","LMS Completed (Ready for Exam)",IF(L34="In Progress","LMS In Progress",IF(H34="Yes","ADD Attended - Awaiting LMS",IF(H34="Rescheduled","ADD Rescheduled",IF(H34="Pending","ADD Scheduled",IF(H34="No","ADD Missed - Follow Up","Initial Prospect")))))))
A35: =IF(B35="","","REC-"&TEXT(35-8,"000")) | P35: =IF(B35="","",IF(L35="Yes","LMS Completed (Ready for Exam)",IF(L35="In Progress","LMS In Progress",IF(H35="Yes","ADD Attended - Awaiting LMS",IF(H35="Rescheduled","ADD Rescheduled",IF(H35="Pending","ADD Scheduled",IF(H35="No","ADD Missed - Follow Up","Initial Prospect")))))))
A36: =IF(B36="","","REC-"&TEXT(36-8,"000")) | P36: =IF(B36="","",IF(L36="Yes","LMS Completed (Ready for Exam)",IF(L36="In Progress","LMS In Progress",IF(H36="Yes","ADD Attended - Awaiting LMS",IF(H36="Rescheduled","ADD Rescheduled",IF(H36="Pending","ADD Scheduled",IF(H36="No","ADD Missed - Follow Up","Initial Prospect")))))))
A37: =IF(B37="","","REC-"&TEXT(37-8,"000")) | P37: =IF(B37="","",IF(L37="Yes","LMS Completed (Ready for Exam)",IF(L37="In Progress","LMS In Progress",IF(H37="Yes","ADD Attended - Awaiting LMS",IF(H37="Rescheduled","ADD Rescheduled",IF(H37="Pending","ADD Scheduled",IF(H37="No","ADD Missed - Follow Up","Initial Prospect")))))))
A38: =IF(B38="","","REC-"&TEXT(38-8,"000")) | P38: =IF(B38="","",IF(L38="Yes","LMS Completed (Ready for Exam)",IF(L38="In Progress","LMS In Progress",IF(H38="Yes","ADD Attended - Awaiting LMS",IF(H38="Rescheduled","ADD Rescheduled",IF(H38="Pending","ADD Scheduled",IF(H38="No","ADD Missed - Follow Up","Initial Prospect")))))))
A39: =IF(B39="","","REC-"&TEXT(39-8,"000")) | P39: =IF(B39="","",IF(L39="Yes","LMS Completed (Ready for Exam)",IF(L39="In Progress","LMS In Progress",IF(H39="Yes","ADD Attended - Awaiting LMS",IF(H39="Rescheduled","ADD Rescheduled",IF(H39="Pending","ADD Scheduled",IF(H39="No","ADD Missed - Follow Up","Initial Prospect")))))))
A40: =IF(B40="","","REC-"&TEXT(40-8,"000")) | P40: =IF(B40="","",IF(L40="Yes","LMS Completed (Ready for Exam)",IF(L40="In Progress","LMS In Progress",IF(H40="Yes","ADD Attended - Awaiting LMS",IF(H40="Rescheduled","ADD Rescheduled",IF(H40="Pending","ADD Scheduled",IF(H40="No","ADD Missed - Follow Up","Initial Prospect")))))))
A41: =IF(B41="","","REC-"&TEXT(41-8,"000")) | P41: =IF(B41="","",IF(L41="Yes","LMS Completed (Ready for Exam)",IF(L41="In Progress","LMS In Progress",IF(H41="Yes","ADD Attended - Awaiting LMS",IF(H41="Rescheduled","ADD Rescheduled",IF(H41="Pending","ADD Scheduled",IF(H41="No","ADD Missed - Follow Up","Initial Prospect")))))))
...

Sheet Recruitment Dashboard
A1: RECRUITMENT PERFORMANCE DASHBOARD & METRICS
A2: Recruitment Funnel Conversion Analysis, Milestone Breakdown & Recruiter Performance
A4: RECRUITMENT PIPELINE FUNNEL ANALYSIS
A5: Funnel Stage | B5: Count | C5: % of Sourced | D5: Conversion / Drop-off Note
A6: 1. Recruits Sourced | B6: ='Recruit Monitoring Tracker'!B5 | C6: =IFERROR(B6/B6,1) | D6: Total candidates identified in pipeline
A7: 2. Attended ADD | B7: ='Recruit Monitoring Tracker'!F5 | C7: =IFERROR(B7/B6,0) | D7: Completed Agency Discovery Day seminar
A8: 3. Started LMS | B8: =COUNTIFS('Recruit Monitoring Tracker'!L9:L65,"<>Not Started",'Recruit Monitoring Tracker'!L9:L65,"<>",'Recruit Monitoring Tracker'!B9:B65,"<>") | C8: =IFERROR(B8/B6,0) | D8: Candidate activated LMS & initiated training
A9: 4. Completed LMS | B9: ='Recruit Monitoring Tracker'!N5 | C9: =IFERROR(B9/B6,0) | D9: Finished 100% of modules & certified
A10: 5. Ready for Exam | B10: =COUNTIF('Recruit Monitoring Tracker'!P9:P65, "*Ready for Exam*") | C10: =IFERROR(B10/B6,0) | D10: Endorsed for Insurance Commission Licensing
A12: ADD ATTENDANCE BREAKDOWN | D12: LMS COMPLETION BREAKDOWN
A13: ADD Status | B13: Count | C13: % Share | D13: LMS Status | E13: Count | F13: % Share
A14: Attended (Yes) | B14: =COUNTIF('Recruit Monitoring Tracker'!H9:H65, "Yes") | C14: =IFERROR(B14/$B$18, 0) | D14: Completed (Yes) | E14: =COUNTIF('Recruit Monitoring Tracker'!L9:L65, "Yes") | F14: =IFERROR(E14/$E$18, 0)
A15: Pending / Scheduled | B15: =COUNTIF('Recruit Monitoring Tracker'!H9:H65, "Pending") | C15: =IFERROR(B15/$B$18, 0) | D15: In Progress | E15: =COUNTIF('Recruit Monitoring Tracker'!L9:L65, "In Progress") | F15: =IFERROR(E15/$E$18, 0)
A16: Rescheduled | B16: =COUNTIF('Recruit Monitoring Tracker'!H9:H65, "Rescheduled") | C16: =IFERROR(B16/$B$18, 0) | D16: Not Started | E16: =COUNTIF('Recruit Monitoring Tracker'!L9:L65, "Not Started") | F16: =IFERROR(E16/$E$18, 0)
A17: Missed / No-Show | B17: =COUNTIF('Recruit Monitoring Tracker'!H9:H65, "No") | C17: =IFERROR(B17/$B$18, 0) | D17: Withdrawn / Dropped | E17: =COUNTIF('Recruit Monitoring Tracker'!L9:L65, "Withdrawn") | F17: =IFERROR(E17/$E$18, 0)
A18: Total | B18: =SUM(B14:B17) | C18: =SUM(C14:C17) | D18: Total | E18: =SUM(E14:E17) | F18: =SUM(F14:F17)
A20: RECRUITER & TEAM PERFORMANCE SUMMARY
A21: Recruiter / Team Leader | B21: Total Sourced | C21: Attended ADD | D21: ADD Rate % | E21: Completed LMS | F21: LMS Rate % | G21: Ready for Exam
A22: Sarah Jenkins (UM) | B22: =COUNTIF('Recruit Monitoring Tracker'!E9:E65, "*Sarah Jenkins (UM)*") | C22: =COUNTIFS('Recruit Monitoring Tracker'!E9:E65, "*Sarah Jenkins (UM)*", 'Recruit Monitoring Tracker'!H9:H65, "Yes") | D22: =IFERROR(C22/B22, 0) | E22: =COUNTIFS('Recruit Monitoring Tracker'!E9:E65, "*Sarah Jenkins (UM)*", 'Recruit Monitoring Tracker'!L9:L65, "Yes") | F22: =IFERROR(E22/C22, 0) | G22: =COUNTIFS('Recruit Monitoring Tracker'!E9:E65, "*Sarah Jenkins (UM)*", 'Recruit Monitoring Tracker'!P9:P65, "*Ready for Exam*")
A23: David Tan | B23: =COUNTIF('Recruit Monitoring Tracker'!E9:E65, "*David Tan*") | C23: =COUNTIFS('Recruit Monitoring Tracker'!E9:E65, "*David Tan*", 'Recruit Monitoring Tracker'!H9:H65, "Yes") | D23: =IFERROR(C23/B23, 0) | E23: =COUNTIFS('Recruit Monitoring Tracker'!E9:E65, "*David Tan*", 'Recruit Monitoring Tracker'!L9:L65, "Yes") | F23: =IFERROR(E23/C23, 0) | G23: =COUNTIFS('Recruit Monitoring Tracker'!E9:E65, "*David Tan*", 'Recruit Monitoring Tracker'!P9:P65, "*Ready for Exam*")
A24: Elena Gomez | B24: =COUNTIF('Recruit Monitoring Tracker'!E9:E65, "*Elena Gomez*") | C24: =COUNTIFS('Recruit Monitoring Tracker'!E9:E65, "*Elena Gomez*", 'Recruit Monitoring Tracker'!H9:H65, "Yes") | D24: =IFERROR(C24/B24, 0) | E24: =COUNTIFS('Recruit Monitoring Tracker'!E9:E65, "*Elena Gomez*", 'Recruit Monitoring Tracker'!L9:L65, "Yes") | F24: =IFERROR(E24/C24, 0) | G24: =COUNTIFS('Recruit Monitoring Tracker'!E9:E65, "*Elena Gomez*", 'Recruit Monitoring Tracker'!P9:P65, "*Ready for Exam*")
A25: Michael Chang | B25: =COUNTIF('Recruit Monitoring Tracker'!E9:E65, "*Michael Chang*") | C25: =COUNTIFS('Recruit Monitoring Tracker'!E9:E65, "*Michael Chang*", 'Recruit Monitoring Tracker'!H9:H65, "Yes") | D25: =IFERROR(C25/B25, 0) | E25: =COUNTIFS('Recruit Monitoring Tracker'!E9:E65, "*Michael Chang*", 'Recruit Monitoring Tracker'!L9:L65, "Yes") | F25: =IFERROR(E25/C25, 0) | G25: =COUNTIFS('Recruit Monitoring Tracker'!E9:E65, "*Michael Chang*", 'Recruit Monitoring Tracker'!P9:P65, "*Ready for Exam*")
A26: Total Agency | B26: =SUM(B22:B25) | C26: =SUM(C22:C25) | D26: =IFERROR(C26/B26, 0) | E26: =SUM(E22:E25) | F26: =IFERROR(E26/C26, 0) | G26: =SUM(G22:G25)

Sheet Dropdowns & Settings
A1: SYSTEM DROPDOWN LISTS & CONFIGURATION REFERENCE
A2: Reference options for tracker dropdown menus, funnel stages, and agency recruiters
A4: ADD ATTENDANCE OPTIONS | D4: LMS COMPLETION OPTIONS | G4: AGENCY RECRUITERS / LEADERS
A5: Option Value | B5: Definition & Action Trigger | D5: Option Value | E5: Definition & Action Trigger | G5: Recruiter Name | H5: Role / Designation
A6: Yes | B6: Candidate attended ADD orientation session. Action: Issue LMS credentials. | D6: Yes | E6: 100% completed & certified. Action: Endorse for Licensing Exam. | G6: Cedric (cedric.axa1@gmail.com) | H6: Agency Leader / Recruiter
A7: No | B7: Candidate missed session (no-show). Action: Call back & re-invite to next batch. | D7: In Progress | E7: Currently taking modules (20%-90%). Action: Check progress & nudge completion. | G7: Sarah Jenkins (UM) | H7: Unit Manager / Agency Leader
A8: Rescheduled | B8: Candidate requested new schedule prior to session. Action: Confirm new batch date. | D8: Not Started | E8: Account created or invited, 0% completed. Action: Resend credentials & setup call. | G8: David Tan | H8: Senior Financial Advisor / Recruiter
A9: Pending | B9: Candidate confirmed attendance for upcoming ADD batch. Action: Send reminder. | D9: Withdrawn | E9: Candidate discontinued application. Action: Archive record or note reason. | G9: Elena Gomez | H9: Agency Recruitment Specialist
G10: Michael Chang | H10: Financial Advisor / Associate
A12: AUTOMATED PIPELINE STAGES & LOGIC EXPLAINED
A13: Pipeline Stage | B13: Trigger Condition in Workbook Formulas
A14: LMS Completed (Ready for Exam) | B14: Completed LMS? = 'Yes' (Highest milestone achieved; endorse to regulatory exam)
A15: LMS In Progress | B15: Completed LMS? = 'In Progress' (Recruit is actively doing training modules)
A16: ADD Attended - Awaiting LMS | B16: Attended ADD? = 'Yes' and LMS not yet started (Ready to receive credentials)
A17: ADD Scheduled | B17: Attended ADD? = 'Pending' (Invite sent, scheduled for orientation)
A18: ADD Rescheduled | B18: Attended ADD? = 'Rescheduled' (Candidate requested future batch)
A19: ADD Missed - Follow Up | B19: Attended ADD? = 'No' (Candidate did not attend; requires urgent re-engagement)

Sheet User Guide & Workflow
A1: RECRUIT MONITORING TRACKER - USER GUIDE & BEST PRACTICES
A2: Step-by-step operating guide for tracking candidate journey from ADD attendance to LMS completion
A4: 1. OVERVIEW & OBJECTIVE
A5: Purpose | B5: This workbook is customized for agency leaders and recruiters to track candidates systematically through the two critical recruitment hurdles: (1) Attending ADD (Agency / Agent Discovery Day) and (2) Completing LMS (Learning Management System pre-licensing training).
A6: Design | B6: Automated KPI summary cards, formula-driven pipeline stage classification, built-in data validation dropdowns, visual color highlighting, and a full executive analytics dashboard.
A8: 2. STEP-BY-STEP RECRUITMENT WORKFLOW
A9: Step 1: Input Recruit Profile | B9: Type the recruit's Complete Name in Column B (Last Name, First Name M.I.). The Recruit ID (Column A) will automatically generate! Enter contact number, email, and the sourcing recruiter.
A10: Step 2: Monitor ADD Attendance | B10: Enter the ADD Scheduled Date in Col G. When the session concludes, set 'Attended ADD?' (Col H) to 'Yes', 'No', or 'Rescheduled' using the dropdown menu. Record the actual date attended in Col I and brief feedback in Col J.
A11: Step 3: Track LMS Completion | B11: Once the recruit passes ADD, issue LMS access (Col K). As the candidate studies, update 'Completed LMS?' (Col L) to 'In Progress' or 'Yes'. Enter their module progress % in Col N (e.g. 50%, 100%) and certification details in Col O.
A12: Step 4: Execute Next Actions | B12: The workbook will automatically update 'Current Pipeline Stage' (Col P). Refer to this column to see who is 'Ready for Exam', who is 'LMS In Progress', and who missed ADD. Enter the Next Action (Col Q) and Follow-up Date (Col R).
A14: 3. KEY METRICS & FORMULA AUTOMATION
A15: Attendance Rate % | B15: Calculates Attended ADD / Total Recruits Sourced. Benchmark target is >= 70%.
A16: Completion Rate % | B16: Calculates Completed LMS / Attended ADD. Benchmark target is >= 60%.
A17: Funnel Conversion % | B17: Calculates Completed LMS / Total Recruits Sourced. Benchmark target is >= 40%.
A18: Adding New Recruits | B18: Rows 15 to 65 are pre-formatted with all dropdowns, formulas, and borders. Simply start typing in Column B (Complete Name), and the entire row will activate automatically!
A20: 4. BEST PRACTICES FOR RECRUITING SUCCESS
A21: The 24-Hour Rule | B21: Reach out to ADD attendees within 24 hours while interest is fresh to set up LMS credentials.
A22: LMS Momentum Window | B22: Encourage recruits to complete the 6 LMS modules within 7 to 10 days before enthusiasm wanes.
A23: Re-scheduling Protocol | B23: For no-shows ('No'), call within 48 hours to offer 1-on-1 career briefing or reschedule to the next ADD batch.
A24: Mock Exam Review | B24: Once LMS is Completed ('Yes'), immediately schedule a practice mock test before filing for the licensing exam.

Sheet ADD Registration Form
A1: AGENCY DISCOVERY DAY (ADD) — REGISTRATION FORM
A2: Candidate Career Orientation Intake Slip | Pre-Licensing Recruitment Pipeline
A4: 1. CANDIDATE PERSONAL INFORMATION
A5: Complete Name: | B5: Last Name, First Name M.I.
A6: Mobile Number: | B6: +63 9XX XXX XXXX | D6: Email Address: | E6: candidate@email.com
A7: Date of Birth: | B7: YYYY-MM-DD | D7: Civil Status: | E7: [ ] Single [ ] Married [ ] Other
A8: City / Address: | B8: City, Province
A10: 2. BACKGROUND & CURRENT OCCUPATION
A11: Current Field: | B11: [ ] Employed [ ] Business [ ] Freelance | D11: Current Company / Role: | E11: Job Title / Employer
A12: Education: | B12: College Degree / Course | D12: Work Experience: | E12: [ ] <1 yr [ ] 1-3 yrs [ ] 3-5 yrs [ ] 5+ yrs
A14: 3. SOURCING & ADD ORIENTATION SCHEDULE
A15: Invited By (Recruiter): | B15: Cedric (cedric.axa1@gmail.com) | D15: Date Invited / Sourced: | E15: 2026-09-15
A16: Preferred ADD Session: | B16: [ ] Saturday Morning (10 AM) [ ] Saturday Afternoon (2 PM) | D16: Orientation Mode: | E16: [ ] Online via Zoom [ ] Branch / In-Person
A18: 4. MOTIVATION & CAREER OBJECTIVES
A19: Primary Motivation: | B19: [ ] Unlimited Income Potential [ ] Flexible Time [ ] Work from Home [ ] Helping Others
A20: Career Mode: | B20: [ ] Full-Time Financial Advisor [ ] Part-Time Financial Advisor [ ] Exploring / Open-Minded
A22: 5. CONFIRMATION & OFFICE USE ONLY
A23: Candidate Signature: | B23: ____________________________ | D23: Date Signed: | E23: ____________________________
A24: --- FOR AGENCY / UNIT MANAGER USE ONLY ---
A25: Assigned Recruit ID: | B25: REC-_____ | D25: ADD Attendance: | E25: [ ] Attended (Date: ________) [ ] Rescheduled
A26: LMS Endorsement: | B26: [ ] Approved for LMS Modules | D26: LMS Setup Date: | E26: Credentials Sent Date: ________
A27: UM / Recruiter Sign: | B27: _______________________ | D27: Overall Status: | E27: [ ] Active In Pipeline [ ] Ready for Exam
